{"name": "test_2_google_search_assertion_failed", "status": "failed", "statusDetails": {"message": "Failed: <Failed instance>", "trace": "assert False\n\nDuring handling of the above exception, another exception occurred:\n<Failed instance>"}, "description": " This is the same google search testcase, but it will fail due to assertion error", "attachments": [{"name": "log", "source": "c5ff5133-5427-4f38-9ae1-687f809e7520-attachment.txt", "type": "text/plain"}], "start": 1599489043834, "stop": 1599489044720, "uuid": "8c27d038-d0f3-4529-ad56-83cb9f1f02dc", "historyId": "97730b26b2236b2affb587fcd7d35a73", "testCaseId": "de97daef3c2b749ec694e8e3e7ac60b9", "fullName": "tests.test_google_page.TestGooglePage#test_2_google_search_assertion_failed", "labels": [{"name": "tag", "value": "@pytest.mark.usefixtures('setup')"}, {"name": "parentSuite", "value": "tests"}, {"name": "suite", "value": "test_google_page"}, {"name": "subSuite", "value": "TestGooglePage"}, {"name": "host", "value": "Jag"}, {"name": "thread", "value": "6268-MainThread"}, {"name": "framework", "value": "pytest"}, {"name": "language", "value": "cpython3"}, {"name": "package", "value": "tests.test_google_page"}]}